Workbook

Sheet Project Info
B2: PROJECT INFO
B3: The single source of truth for project identity. Dashboard, every log's header, and every Skill-drafted document pull from here — fill it in once per project.
B5: Project Name | C5: Norcross, GA
B6: Project Number | C6: #1517
B7: Job Number | C7: 15170000GR
B8: Project Address | C8: 4990 Jimmy Carter Blvd, Norcross, GA 30093
B9: AHJ / Jurisdiction | C9: Gwinnett County, GA; Norcross, GA
B11: Owner | C11: Lidl US Operations, LLC
B12: Owner Contact (name / email / phone) | C12: Jens Byer / jens.byer@lidl.us / 571-867-0856
B13: Architect / Design Firm | C13: Progressive Companies
B14: Architect Contact
B15: General Contractor | C15: Place Services, Inc
B16: GC Project Manager | C16: Bobby McTeague
B17: GC Superintendent | C17: Tim Mauldin
B19: Contract Type / Delivery Method | C19: Lump Sum
B20: Contract Date
B21: Notice to Proceed Date | C21: 46290
B22: Substantial Completion Date (Contract) | C22: 46559
B24: Original Contract Value ($) | C24: 7958879
B25: Approved Change Orders to Date ($) | C25: =SUMIFS('Change Order Log'!H2:H299,'Change Order Log'!J2:J299,"Approved") -> 0
B26: Current Contract Value ($) | C26: =C24+C25 -> 7958879
B28: Prepared By | C28: Luis Marcelino
B29: Preparer Company | C29: Place Services, Inc
B30: Last Updated | C30: =TODAY() -> 46296
B32: Cells shaded light gray are for manual entry. Approved Change Orders, Current Contract Value, and Last Updated are live formulas — don't type over them.

Sheet README
B2: PROJECT CONTROL TRACKER — HOW THIS WORKBOOK WORKS
B5: This is the shared tracker the Claude Skills in this pack read from and write to.
B7: TABS:
B8: Project Info Project identity — name, number, owner, contract dates, team, the
B9: preparer. Fill this in ONCE per project; everything else reads from it.
B10: Dashboard Live counts and totals pulled from every log below.
B11: RFI Log One row per RFI. Status/Days Open/Overdue calculate automatically;
B12: Void? flags a voided RFI, Revision # tracks reissues.
B13: Submittal Log One row per submittal package.
B14: Change Order Log GC -> OWNER: PCO through to executed CO, linked back to RFIs/Claims.
B15: Trade(s) tags which trade(s) the cost/backup applies to.
B16: Subcontractor CO Log SUB -> GC: change orders a subcontractor submitted for your review,
... B132: Delete the example (row 2) on every log tab before starting real project data.

Sheet Dashboard
B2: PROJECT CONTROL DASHBOARD
B3: Auto-calculated from every log below. Project identity is set once, on the Project Info tab.
B5: Project Name: | C5: =IF('Project Info'!C5="","",'Project Info'!C5) -> Norcross, GA
B6: Project Number: | C6: =IF('Project Info'!C6="","",'Project Info'!C6) -> #1517
B7: Report Date: | C7: =TODAY() -> 46296
B10: RFIs
B11: Open | C11: =COUNTIF('RFI Log'!K2:K299,"Open") -> 0
B12: Overdue | C12: =COUNTIF('RFI Log'!K2:K299,"Overdue") -> 0
B13: Closed | C13: =COUNTIF('RFI Log'!K2:K299,"Closed") -> 6
B14: Submittals
B15: Pending / in review | C15: =COUNTIFS('Submittal Log'!G2:G299,"<>",'Submittal Log'!I2:I299,"") -> 8
B16: Revise & Resubmit | C16: =COUNTIF('Submittal Log'!J2:J299,"Revise & Resubmit") -> 0
B17: Change Orders
B18: Pending | C18: =COUNTIF('Change Order Log'!J2:J299,"Pending") -> 2
B19: Approved value ($) | C19: =SUMIFS('Change Order Log'!H2:H299,'Change Order Log'!J2:J299,"Approved") -> 0
B20: Subcontractor Change Orders
B21: Under review | C21: =COUNTIF('Subcontractor CO Log'!K2:K299,"Under Review") -> 0
B22: Rejected | C22: =COUNTIF('Subcontractor CO Log'!K2:K299,"Rejected") -> 0
B23: Approved value ($) | C23: =SUMIFS('Subcontractor CO Log'!N2:N299,'Subcontractor CO Log'!K2:K299,"Approved") -> 56430
B24: Claims
B25: Open | C25: =COUNTIF('Claims Log'!K2:K299,"Open") -> 0
B26: Late notice (non-compliant) | C26: =COUNTIF('Claims Log'!F2:F299,"NO - LATE") -> 0
B27: Risk Register
B28: High priority, open | C28: =COUNTIFS('Risk Register'!H2:H299,"High",'Risk Register'!M2:M299,"Open") -> 0
B29: Total open risks | C29: =COUNTIF('Risk Register'!M2:M299,"Open") -> 0
B30: Action Items (Meeting Minutes)
B31: Open | C31: =COUNTIF('Meeting Minutes Log'!I2:I299,"Open") -> 12
B32: Overdue | C32: =SUMPRODUCT(('Meeting Minutes Log'!$H$2:$H$299<>"")*('Meeting Minutes Log'!$H$2:$H$299<TODAY())*('Meeting Minutes Log'!$I$2:$I$299<>"Closed")) -> 0
B33: Contract Review
B34: High-risk deviations, open | C34: =COUNTIFS('Contract Review Log'!G2:G299,"High",'Contract Review Log'!I2:I299,"Open") -> 0
B35: Contract Milestones
B36: Missed | C36: =COUNTIF('Contract Milestones'!D2:D296,"Missed") -> 0
B37: Met late | C37: =COUNTIF('Contract Milestones'!D2:D296,"Met - Late") -> 0
B38: Due soon (14 days) | C38: =COUNTIF('Contract Milestones'!D2:D296,"Due Soon") -> 0
B39: Permits
B40: Action needed | C40: =COUNTIF('Permit Tracker'!J6:J303,"ACTION NEEDED") -> 0
B41: Expiring soon (30 days) | C41: =COUNTIF('Permit Tracker'!J6:J303,"EXPIRING SOON") -> 0
B42: Issued / in hand | C42: =COUNTIF('Permit Tracker'!E6:E303,"In Hand") -> 0
B43: Procurement / Materials
B44: Not ordered | C44: =COUNTIF('Material Tracker'!F6:F303,"Not Ordered") -> 0
...

Sheet RFI Log
A1: RFI # | B1: Date Submitted | C1: Submitted By | D1: Subject | E1: Spec Section / Drawing Ref | F1: Question | G1: Assigned To | H1: Response Due Date | I1: Response | J1: Date Answered | K1: Status | L1: Days Open | M1: Cost Impact ($) | N1: Schedule Impact (days) | O1: Linked CO # | P1: Linked Submittal # | Q1: Backup Documents | R1: Backup Required? | S1: Revision # | T1: Void? | U1: Last Activity Date | V1: Days Since Activity
A2: RFI-001 | B2: 46119 | C2: Luis Marcelino, Place Services Inc. | D2: Civil CAD File - Waiver & CAD Release (Lidl portal RFI #58) | E2: Civil plan set (CHA Project No. 20-LD-073); no sheet/spec # listed | F2: Can you provide the Waiver and CAD for the Civil plan for the Site Contractor to start working on his import? | G2: Christopher Manes, CHA Consulting, Inc. | H2: 46122 | I2: Sign the attached AutoCAD data release letter (dated 04/17/26) and return to C. Manes (CHA); CAD file to be provided upon receipt of signed letter. Portal status: Closed 08/26/26. | J2: 46129 | K2: =IF(A2="","",IF(T2="Yes","Void",IF(I2<>"","Closed",IF(AND(H2<>"",TODAY()>H2),"Overdue","Open")))) -> Closed | L2: =IF(A2="","",IF(I2<>"",J2-B2,TODAY()-B2)) -> 10 | M2: 0 | N2: 0 | Q2: AutoCAD data release letter_04.17.26.pdf (included in RFI portal export) | R2: No | S2: 0 | T2: No | U2: =IF(A2="","",MAX(B2+0,H2+0,J2+0)) -> 46129 | V2: =IF(A2="","",IF(K2="Closed","",TODAY()-U2))
A3: RFI-002 | B3: 46119 | C3: Luis Marcelino, Place Services Inc. | D3: Storm Structures - New vs. Existing (Lidl portal RFI #59) | E3: Civil storm drainage: STR15X, STR16X, STR17, STR18X (STR19X added in response); no sheet # listed | F3: Confirm STR15X (Junction Box), STR16X (Junction Box) and STR18X (Double Wing Catch Basin), and whether STR17 (not labeled "X" but has an existing pipe connected) is an existing structure to remain, to define scope without gaps/overlaps with suppliers. | G3: Jeff Belyea, CHA Consulting, Inc. | H3: 46122 | I3: Storm structures 15x, 16x, 17, and 19x are new structures to be set on the existing storm system. Storm structure 18x is an existing structure to remain. (J. Belyea, 04/08/26) | J3: 46120 | K3: =IF(A3="","",IF(T3="Yes","Void",IF(I3<>"","Closed",IF(AND(H3<>"",TODAY()>H3),"Overdue","Open")))) -> Closed | L3: =IF(A3="","",IF(I3<>"",J3-B3,TODAY()-B3)) -> 1 | M3: 0 | N3: 0 | R3: No | S3: 0 | T3: No | U3: =IF(A3="","",MAX(B3+0,H3+0,J3+0)) -> 46122 | V3: =IF(A3="","",IF(K3="Closed","",TODAY()-U3))
A4: RFI-003 | B4: 46127 | C4: Luis Marcelino, Place Services Inc. | D4: Storefront System - Kawneer vs. Schaal (Lidl portal RFI #60) | E4: Storefront system (BOD Kawneer; Schaal national account); no sheet/spec # listed | F4: BOD is Kawneer but Schaal is National Account. Are we able to use the Kawneer system? | G4: Progressive Companies - Shelley Chovan (also Gabriela Camarillo, Jenna Giha, Stacey Vroman) | H4: 46132 | I4: Schaal must be used. (S. Chovan, 04/20/26) | J4: 46132 | K4: =IF(A4="","",IF(T4="Yes","Void",IF(I4<>"","Closed",IF(AND(H4<>"",TODAY()>H4),"Overdue","Open")))) -> Closed | L4: =IF(A4="","",IF(I4<>"",J4-B4,TODAY()-B4)) -> 5 | M4: 0 | N4: 0 | R4: No | S4: 0 | T4: No | U4: =IF(A4="","",MAX(B4+0,H4+0,J4+0)) -> 46132 | V4: =IF(A4="","",IF(K4="Closed","",TODAY()-U4))
A5: RFI-004 | B5: 46260 | C5: Luis Marcelino, Place Services Inc. | D5: Arch + MEP CAD Release (Lidl portal RFI #61) | E5: Architectural and MEP drawings; no sheet # listed | F5: Can you please provide CAD for the Arch and MEPs? | G5: Progressive Companies - Amy Schoch (also Alex Hengstebeck, Gabriela Camarillo, Jenna Giha, Shelley Chovan, Stacey Vroman) | H5: 46265 | I5: CAD Release with PSI has been completed and CAD files were sent on 9/2/26. If the GC needs additional CAD files, send via email to the Progressive team and NOT an RFI. (A. Schoch, 09/08/26) | J5: 46273 | K5: =IF(A5="","",IF(T5="Yes","Void",IF(I5<>"","Closed",IF(AND(H5<>"",TODAY()>H5),"Overdue","Open")))) -> Closed | L5: =IF(A5="","",IF(I5<>"",J5-B5,TODAY()-B5)) -> 13 | M5: 0 | N5: 0 | Q5: Lidl Norcross GA - RFI 61 - Arch and MEP CAD Release_PC Response.pdf (included in RFI portal export) | R5: No | S5: 0 | T5: No | U5: =IF(A5="","",MAX(B5+0,H5+0,J5+0)) -> 46273 | V5: =IF(A5="","",IF(K5="Closed","",TODAY()-U5))
A6: RFI-005 | B6: 46265 | C6: Luis Marcelino, Place Services Inc. | D6: HVAC - BMS Integration (Airius Destratification Fans) & Fire/Smoke Dampers (Lidl portal RFI #62) | E6: HVAC / destratification fan schedule; mechanical drawings (no sheet # listed) | F6: 1. Airius Destratification Fans: Airius advises BMS integration is not available with the basis-of-design model number - please advise. 2. Fire/Smoke Dampers: none shown on the drawings - are we to exclude? | G6: Progressive Companies - Amy Schoch (also Alex Hengstebeck, Gabriela Camarillo, Jenna Giha, Shelley Chovan, Stacey Vroman) | H6: 46268 | I6: 1. Provide destratification fans as called out in the schedule; fans to be set up for operation independent of BMS. 2. No fire/smoke dampers required; ducts are not penetrating any fire rated partitions. (J. Martinez Sabag, Mech. Eng. Designer, 09/11/26) | J6: 46276 | K6: =IF(A6="","",IF(T6="Yes","Void",IF(I6<>"","Closed",IF(AND(H6<>"",TODAY()>H6),"Overdue","Open")))) -> Closed | L6: =IF(A6="","",IF(I6<>"",J6-B6,TODAY()-B6)) -> 11 | M6: 0 | N6: 0 | Q6: Lidl Norcross GA - RFI 62 - HVAC - BMS Integration and Dampers_PC Response.pdf (included in RFI portal export) | R6: No | S6: 0 | T6: No | U6: =IF(A6="","",MAX(B6+0,H6+0,J6+0)) -> 46276 | V6: =IF(A6="","",IF(K6="Closed","",TODAY()-U6))
A7: RFI-006 | B7: 46283 | C7: Tucker Teague, Place Services Inc. | D7: Signal Plans Not Included in Authorized Plan Set (Lidl portal RFI #63) | E7: Traffic signal plans; Authorized plan set AUTHORIZED-EPN2024-00519 (Gwinnett County) | F7: Traffic Improvements Sub submitted signal plans to Gwinnett County; E. Diamond (County Traffic Mgmt Systems Engineer) advised they are not in the authorized plan set and has requested CHA coordinate directly with the County to resolve. Please have the appropriate CHA representative contact E. Diamond and provide required information/revised documentation. | G7: CHA Consulting, Inc. - Christopher Manes (also JaWanna English-Neal, Jeff Belyea, Todd Seldomridge) | H7: 46288 | I7: Final stamped plans from the County Traffic team were included in the Authorized plan set approved by Planning and Development. Authorized plans attached for reference; these are the documents to be used for construction. (C. Manes, 09/23/26; portal status Closed 09/28/26) | J7: 46288 | K7: =IF(A7="","",IF(T7="Yes","Void",IF(I7<>"","Closed",IF(AND(H7<>"",TODAY()>H7),"Overdue","Open")))) -> Closed | L7: =IF(A7="","",IF(I7<>"",J7-B7,TODAY()-B7)) -> 5 | M7: 0 | N7: 0 | Q7: #1517 Lidl Norcross, GA - Traffic Management Systems Engineer Contact Information.png; #1517 Lidl Norcross, GA - RFI - Signal Plans Not Included in Authorized Plan Set.pdf; AUTHORIZED-EPN2024-00519.pdf (response) | R7: Yes | S7: 0 | T7: No | U7: =IF(A7="","",MAX(B7+0,H7+0,J7+0)) -> 46288 | V7: =IF(A7="","",IF(K7="Closed","",TODAY()-U7))
K8: =IF(A8="","",IF(T8="Yes","Void",IF(I8<>"","Closed",IF(AND(H8<>"",TODAY()>H8),"Overdue","Open")))) | L8: =IF(A8="","",IF(I8<>"",J8-B8,TODAY()-B8)) | U8: =IF(A8="","",MAX(B8+0,H8+0,J8+0)) | V8: =IF(A8="","",IF(K8="Closed","",TODAY()-U8))
K9: =IF(A9="","",IF(T9="Yes","Void",IF(I9<>"","Closed",IF(AND(H9<>"",TODAY()>H9),"Overdue","Open")))) | L9: =IF(A9="","",IF(I9<>"",J9-B9,TODAY()-B9)) | U9: =IF(A9="","",MAX(B9+0,H9+0,J9+0)) | V9: =IF(A9="","",IF(K9="Closed","",TODAY()-U9))
K10: =IF(A10="","",IF(T10="Yes","Void",IF(I10<>"","Closed",IF(AND(H10<>"",TODAY()>H10),"Overdue","Open")))) | L10: =IF(A10="","",IF(I10<>"",J10-B10,TODAY()-B10)) | U10: =IF(A10="","",MAX(B10+0,H10+0,J10+0)) | V10: =IF(A10="","",IF(K10="Closed","",TODAY()-U10))
K11: =IF(A11="","",IF(T11="Yes","Void",IF(I11<>"","Closed",IF(AND(H11<>"",TODAY()>H11),"Overdue","Open")))) | L11: =IF(A11="","",IF(I11<>"",J11-B11,TODAY()-B11)) | U11: =IF(A11="","",MAX(B11+0,H11+0,J11+0)) | V11: =IF(A11="","",IF(K11="Closed","",TODAY()-U11))
K12: =IF(A12="","",IF(T12="Yes","Void",IF(I12<>"","Closed",IF(AND(H12<>"",TODAY()>H12),"Overdue","Open")))) | L12: =IF(A12="","",IF(I12<>"",J12-B12,TODAY()-B12)) | U12: =IF(A12="","",MAX(B12+0,H12+0,J12+0)) | V12: =IF(A12="","",IF(K12="Closed","",TODAY()-U12))
K13: =IF(A13="","",IF(T13="Yes","Void",IF(I13<>"","Closed",IF(AND(H13<>"",TODAY()>H13),"Overdue","Open")))) | L13: =IF(A13="","",IF(I13<>"",J13-B13,TODAY()-B13)) | U13: =IF(A13="","",MAX(B13+0,H13+0,J13+0)) | V13: =IF(A13="","",IF(K13="Closed","",TODAY()-U13))
K14: =IF(A14="","",IF(T14="Yes","Void",IF(I14<>"","Closed",IF(AND(H14<>"",TODAY()>H14),"Overdue","Open")))) | L14: =IF(A14="","",IF(I14<>"",J14-B14,TODAY()-B14)) | U14: =IF(A14="","",MAX(B14+0,H14+0,J14+0)) | V14: =IF(A14="","",IF(K14="Closed","",TODAY()-U14))
K15: =IF(A15="","",IF(T15="Yes","Void",IF(I15<>"","Closed",IF(AND(H15<>"",TODAY()>H15),"Overdue","Open")))) | L15: =IF(A15="","",IF(I15<>"",J15-B15,TODAY()-B15)) | U15: =IF(A15="","",MAX(B15+0,H15+0,J15+0)) | V15: =IF(A15="","",IF(K15="Closed","",TODAY()-U15))
K16: =IF(A16="","",IF(T16="Yes","Void",IF(I16<>"","Closed",IF(AND(H16<>"",TODAY()>H16),"Overdue","Open")))) | L16: =IF(A16="","",IF(I16<>"",J16-B16,TODAY()-B16)) | U16: =IF(A16="","",MAX(B16+0,H16+0,J16+0)) | V16: =IF(A16="","",IF(K16="Closed","",TODAY()-U16))
K17: =IF(A17="","",IF(T17="Yes","Void",IF(I17<>"","Closed",IF(AND(H17<>"",TODAY()>H17),"Overdue","Open")))) | L17: =IF(A17="","",IF(I17<>"",J17-B17,TODAY()-B17)) | U17: =IF(A17="","",MAX(B17+0,H17+0,J17+0)) | V17: =IF(A17="","",IF(K17="Closed","",TODAY()-U17))
K18: =IF(A18="","",IF(T18="Yes","Void",IF(I18<>"","Closed",IF(AND(H18<>"",TODAY()>H18),"Overdue","Open")))) | L18: =IF(A18="","",IF(I18<>"",J18-B18,TODAY()-B18)) | U18: =IF(A18="","",MAX(B18+0,H18+0,J18+0)) | V18: =IF(A18="","",IF(K18="Closed","",TODAY()-U18))
K19: =IF(A19="","",IF(T19="Yes","Void",IF(I19<>"","Closed",IF(AND(H19<>"",TODAY()>H19),"Overdue","Open")))) | L19: =IF(A19="","",IF(I19<>"",J19-B19,TODAY()-B19)) | U19: =IF(A19="","",MAX(B19+0,H19+0,J19+0)) | V19: =IF(A19="","",IF(K19="Closed","",TODAY()-U19))
... K298: =IF(A298="","",IF(T298="Yes","Void",IF(I298<>"","Closed",IF(AND(H298<>"",TODAY()>H298),"Overdue","Open")))) | L298: =IF(A298="","",IF(I298<>"",J298-B298,TODAY()-B298)) | U298: =IF(A298="","",MAX(B298+0,H298+0,J298+0)) | V298: =IF(A298="","",IF(K298="Closed","",TODAY()-U298))
A301: Legend: gray-filled columns are for manual entry. Status, Days Open auto-calculate — Status reads Void? first, then Closed/Overdue/Open. Revision # increments each time an RFI is reissued/revised (0 = original). Last Activity Date is the most recent of Date Submitted/Response Due/Date Answered; Days Since Activity flags in red at 14+ days on anything not Closed — this is what feeds the Dashboard's Stale Items section. Row 2 is an example — delete before use.

Sheet Submittal Log
A1: Submittal # | B1: Spec Section | C1: Description | D1: Type | E1: Subcontractor | F1: Date Rec'd from Sub | G1: Date Sent to Architect | H1: Required Return Date | I1: Date Returned | J1: Status | K1: Days in Review | L1: Linked RFI # | M1: Backup Documents | N1: Backup Required? | O1: Last Activity Date | P1: Days Since Activity
A2: SUB-001 | B2: 23 0503 | C2: HVAC Package Rev 0 (Procore 230503-1.0 / Fieldwire PSI-0004) - Lennox RTUs & mini-split, CaptiveAire, ductwork, Greenheck/Titus & Fantech/Airius air distribution, prelim TAB. Reviewer: Make Corrections Noted 9/14 - provide missing EF-1 & air terminal info (addressed in Rev 1). Req'd return = 14-day default; Procore had no due date. | D2: Product Data | E2: Platinum Air Systems | F2: 46268 | G2: 46274 | H2: 46288 | I2: 46289 | J2: Approved as Noted | K2: =IF(A2="","",IF(I2<>"",I2-G2,IF(G2<>"",TODAY()-G2,""))) -> 15 | M2: SUB-001_R1_Original_Procore_Export_2026-10-01.pdf; Submittal-001_Transmittal_Packaged.pdf (package INCLUDED, 659 pp); SUB-001_R0_Reviewed_MakeCorrectionsNoted_2026-09-14.pdf; SUB-001_R1_Reviewed_MakeCorrectionsNoted_2026-09-28.pdf; SUB-001_R1_As-Submitted_PSI-0004_2026-09-22.pdf - folder: documents\submittals\SUB-001 - 230503 HVAC | N2: Yes | O2: =IF(A2="","",MAX(F2+0,G2+0,H2+0,I2+0)) -> 46289 | P2: =IF(A2="","",IF(OR(J2="Approved",J2="Approved as Noted"),"",TODAY()-O2))
A3: SUB-001-R1 | B3: 23 0503 | C3: HVAC Package Rev 1 (Procore 230503-1.1) - corrections made; EF-1 (SE1-10-440-VG) & Titus air terminals added. Reviewer: Make Corrections Noted 9/28 - OPEN: provide TG-1 per plans and diffuser/register/grille schedule. Procore still Open, ball in court Amy Schoch (Progressive). | D3: Product Data | E3: Platinum Air Systems | F3: 46287 | G3: 46287 | H3: 46309 | I3: 46293 | J3: Approved as Noted | K3: =IF(A3="","",IF(I3<>"",I3-G3,IF(G3<>"",TODAY()-G3,""))) -> 6 | M3: SUB-001_R1_Original_Procore_Export_2026-10-01.pdf; Submittal-001_Transmittal_Packaged.pdf (package INCLUDED, 659 pp); SUB-001_R0_Reviewed_MakeCorrectionsNoted_2026-09-14.pdf; SUB-001_R1_Reviewed_MakeCorrectionsNoted_2026-09-28.pdf; SUB-001_R1_As-Submitted_PSI-0004_2026-09-22.pdf - folder: documents\submittals\SUB-001 - 230503 HVAC | N3: Yes | O3: =IF(A3="","",MAX(F3+0,G3+0,H3+0,I3+0)) -> 46309 | P3: =IF(A3="","",IF(OR(J3="Approved",J3="Approved as Noted"),"",TODAY()-O3))
A4: SUB-002 | B4: 33 4100 | C4: Stormwater Package Rev 0 (Procore 33 4100-2.0 / Fieldwire PSI-0002) - Hydro International First Defense hydrodynamic separator (ST8), Up-Flo water quality filter (ST5), Southeast Culvert 84in CMP underground detention. Reviewer: CHA Consulting (Christopher Manes) - no response. Req'd return per Fieldwire response due 9/9; Procore has no due date. | D4: Product Data | E4: Coles Construction | F4: 46260 | G4: 46260 | H4: 46274 | J4: Pending | K4: =IF(A4="","",IF(I4<>"",I4-G4,IF(G4<>"",TODAY()-G4,""))) -> 36 | M4: SUB-002_R0_Original_Procore_Export_2026-10-01.pdf; Submittal-002_Transmittal_Packaged.pdf (package INCLUDED, 62 pp) - folder: documents\submittals\SUB-002 - 334100 Storm Drainage | N4: Yes | O4: =IF(A4="","",MAX(F4+0,G4+0,H4+0,I4+0)) -> 46274 | P4: =IF(A4="","",IF(OR(J4="Approved",J4="Approved as Noted"),"",TODAY()-O4)) -> 22
A5: SUB-003 | B5: 33 4100 | C5: HDPE Pipe Rev 0 (Procore 33 4100-1.0, Package #1 Site Utilities / Fieldwire PSI-0001) - ADS N-12 ST IB storm pipe (pkg Section 1). Attachment is the full Core & Main site utility package; Procore splits Package #1 into one item per spec section (sanitary = SUB-004). Reviewer: CHA Consulting (Christopher Manes) - no response. Req'd return per Fieldwire response due 9/11; Procore has no due date. | D5: Product Data | E5: Coles Construction (supplier Core & Main) | F5: 46260 | G5: 46260 | H5: 46276 | J5: Pending | K5: =IF(A5="","",IF(I5<>"",I5-G5,IF(G5<>"",TODAY()-G5,""))) -> 36 | M5: SUB-003_R0_Original_Procore_Export_2026-10-01.pdf; Submittal-003_Transmittal_Packaged.pdf (package INCLUDED, 92 pp) - folder: documents\submittals\SUB-003 - 334100 Site Utilities | N5: Yes | O5: =IF(A5="","",MAX(F5+0,G5+0,H5+0,I5+0)) -> 46276 | P5: =IF(A5="","",IF(OR(J5="Approved",J5="Approved as Noted"),"",TODAY()-O5)) -> 20
A6: SUB-004 | B6: 33 3000 | C6: Sanitary Sewer Rev 0 (Procore 33 3000-1.0, Package #1 Site Utilities / Fieldwire PSI-0001) - Diamond Sani-21 PVC sewer pipe & fittings, cleanouts, Star Pipe heavy-duty covers, marking tape (pkg Section 2, export pp. 8-19). Same PSI-0001 attachment as SUB-003. Reviewer: CHA Consulting (Christopher Manes) - no response. Req'd return per Fieldwire response due 9/11; Procore has no due date. | D6: Product Data | E6: Coles Construction (supplier Core & Main) | F6: 46260 | G6: 46260 | H6: 46276 | J6: Pending | K6: =IF(A6="","",IF(I6<>"",I6-G6,IF(G6<>"",TODAY()-G6,""))) -> 36 | M6: SUB-004_R0_Original_Procore_Export_2026-10-01.pdf; SUB-004_R0_Sanitary_Section_Only.pdf; Submittal-004_Transmittal_Packaged.pdf (package INCLUDED, 92 pp) - folder: documents\submittals\SUB-004 - 333000 Sanitary Sewer | N6: Yes | O6: =IF(A6="","",MAX(F6+0,G6+0,H6+0,I6+0)) -> 46276 | P6: =IF(A6="","",IF(OR(J6="Approved",J6="Approved as Noted"),"",TODAY()-O6)) -> 20
A7: SUB-005 | B7: 33 1000 | C7: Domestic Water & Irrigation Rev 0 (Procore 33 1000-1.0, Package #1 Site Utilities / Fieldwire PSI-0001) - PVC pressure pipe & DI fittings, 2in tap assemblies (Smith-Blair 313, Ford Meter Box), 2in DCV (Wilkins 950XLT), irrigation, 2in RPZ (Wilkins 975XL2) (pkg Section 3, export pp. 20-53). Same PSI-0001 attachment as SUB-003/004. Reviewer: CHA Consulting (Christopher Manes) - no response. Req'd return per Fieldwire response due 9/11; Procore has no due date. | D7: Product Data | E7: Coles Construction (supplier Core & Main) | F7: 46260 | G7: 46260 | H7: 46276 | J7: Pending | K7: =IF(A7="","",IF(I7<>"",I7-G7,IF(G7<>"",TODAY()-G7,""))) -> 36 | M7: SUB-005_R0_Original_Procore_Export_2026-10-01.pdf; SUB-005_R0_Domestic_Water_Section_Only.pdf; Submittal-005_Transmittal_Packaged.pdf (package INCLUDED, 92 pp) - folder: documents\submittals\SUB-005 - 331000 Domestic Water | N7: Yes | O7: =IF(A7="","",MAX(F7+0,G7+0,H7+0,I7+0)) -> 46276 | P7: =IF(A7="","",IF(OR(J7="Approved",J7="Approved as Noted"),"",TODAY()-O7)) -> 20
A8: SUB-006 | B8: 33 | C8: Fire Main Rev 0 (Procore 33-1.0, Package #1 Site Utilities) - U.S. Pipe Tyton DI pipe & fittings, tapping sleeve, M&H 129 hydrant, 8in DCDA BFP vault (Wilkins 350ASTDA), 8in PIV, 8in gate valve (PSI-0001 pkg Section 4, export pp. 54-91). FLAG: Procore item has NO ATTACHMENT (cover only) and spec is division-level '33 - Utilities' - confirm CHA has the fire main cut sheets. Reviewer: CHA Consulting (Christopher Manes) - no response. Req'd return per Fieldwire response due 9/11. | D8: Product Data | E8: Coles Construction (supplier Core & Main) | F8: 46260 | G8: 46260 | H8: 46276 | J8: Pending | K8: =IF(A8="","",IF(I8<>"",I8-G8,IF(G8<>"",TODAY()-G8,""))) -> 36 | M8: SUB-006_R0_Procore_Cover_Only_2026-10-01.pdf (Procore item has NO attachment); SUB-006_R0_Fire_Main_Section_REFERENCE_from_PSI-0001.pdf (from SUB-003 copy); Submittal-006_Transmittal_Packaged.pdf (42 pp) - folder: documents\submittals\SUB-006 - 33 Fire Main | N8: Yes | O8: =IF(A8="","",MAX(F8+0,G8+0,H8+0,I8+0)) -> 46276 | P8: =IF(A8="","",IF(OR(J8="Approved",J8="Approved as Noted"),"",TODAY()-O8)) -> 20
A9: SUB-007 | B9: 22 (22 1119) | C9: Plumbing Package Rev 0 (Procore 22-1.0, Package #2 Plumbing / Fieldwire PSI-0003) - fixtures (DF, L, WC, SK-1/2/3), hydrants, floor drains/sinks, PRV, EWH-1, gas meter. Procore CLOSED. Reviewer (Progressive, bizons 9/25): Make Corrections Noted - OPEN: SK-3 replace Elkay SS8354LR4 with Elkay 14-3C16X20-L-18X per CCD 01 (05/28/2026). Returned 14 days after 9/11 due date. | D9: Product Data | E9: Golden Hands Plumbing (supplier Cowan Supply) | F9: 46260 | G9: 46268 | H9: 46276 | I9: 46290 | J9: Approved as Noted | K9: =IF(A9="","",IF(I9<>"",I9-G9,IF(G9<>"",TODAY()-G9,""))) -> 22 | M9: SUB-007_R0_Original_Procore_Export_2026-10-01.pdf; SUB-007_R0_Reviewed_MakeCorrectionsNoted_2026-09-25.pdf; SUB-007_R0_As-Submitted_PSI-0003_2026-09-03.pdf; Submittal-007_Transmittal_Packaged.pdf (package INCLUDED, 217 pp) - folder: documents\submittals\SUB-007 - 22 Plumbing | N9: Yes | O9: =IF(A9="","",MAX(F9+0,G9+0,H9+0,I9+0)) -> 46290 | P9: =IF(A9="","",IF(OR(J9="Approved",J9="Approved as Noted"),"",TODAY()-O9))
A10: SUB-008 | B10: None (Procore '1 - Default') | C10: CCTV Submittal Rev 0 (Procore 1-3.0 / Fieldwire PSI-0007) - off-site traffic signal Gwinnett Co. TS-082, Jimmy Carter Blvd @ Shelby Dr: AXIS Q6086-E PTZ camera, Major Custom Cable CAT6 100ft, DITEK DTK-MRJPOES surge protector, AXIS TQ5001-E mount (Utilicom quote 62085). No spec section assigned. Reviewer: CHA Consulting (Christopher Manes) - no response; confirm whether Gwinnett DOT review also required. Req'd return per Fieldwire response due 9/25. | D10: Product Data | E10: R.J. Haynie & Associates (supplier Utilicom Supply Associates) | F10: 46265 | G10: 46283 | H10: 46290 | J10: Pending | K10: =IF(A10="","",IF(I10<>"",I10-G10,IF(G10<>"",TODAY()-G10,""))) -> 13 | M10: SUB-008_R0_Original_Procore_Export_2026-10-01.pdf; Submittal-008_Transmittal_Packaged.pdf (package INCLUDED, 18 pp) - folder: documents\submittals\SUB-008 - CCTV Traffic Signal | N10: Yes | O10: =IF(A10="","",MAX(F10+0,G10+0,H10+0,I10+0)) -> 46290 | P10: =IF(A10="","",IF(OR(J10="Approved",J10="Approved as Noted"),"",TODAY()-O10)) -> 6
A11: SUB-009 | B11: None (Procore '1 - Default') | C11: Mast Arm Pole Shop Drawings #1-#3 Rev 0 (Procore 1-2.0 / Fieldwire PSI-0006) - off-site traffic signal Gwinnett Co. TS-082, Jimmy Carter Blvd @ Shelby Dr: Valmont GA672263P1 (2 sheets, GA PE sealed 8/31) Poles B (22ft, 65+55ft arms) & C (30ft, 55+55ft arms) + orientation sketch. FLAG: foundation callout (3ft dia x 14.5ft, (8) #10) is an unsigned annotation, not on sealed dwg - verify. Reviewer: CHA Consulting (Christopher Manes) - no response; confirm Gwinnett DOT review. Req'd return per Fieldwire due 9/25. | D11: Shop Drawing | E11: R.J. Haynie & Associates (Valmont via DOT Lighting / Traffic & Lighting Corp) | F11: 46265 | G11: 46283 | H11: 46290 | J11: Pending | K11: =IF(A11="","",IF(I11<>"",I11-G11,IF(G11<>"",TODAY()-G11,""))) -> 13 | M11: SUB-009_R0_Original_Procore_Export_2026-10-01.pdf; Submittal-009_Transmittal_Packaged.pdf (package INCLUDED, 6 pp) - folder: documents\submittals\SUB-009 - Mast Arm Poles | N11: Yes | O11: =IF(A11="","",MAX(F11+0,G11+0,H11+0,I11+0)) -> 46290 | P11: =IF(A11="","",IF(OR(J11="Approved",J11="Approved as Noted"),"",TODAY()-O11)) -> 6
A12: SUB-010 | B12: None (Procore '1 - Default') | C12: Mast Arm Pole Submittals Rev 0 (Procore 1-1.0 / Fieldwire PSI-0005) - Valmont structural calcs, Order 672263-P1 (94 pp), Poles B (P22 M65/M55) & C (P30 M55/M55), AASHTO 2015, 115 mph - off-site signal Gwinnett Co. TS-082. Related to SUB-009 shop dwgs. FLAG: calcs give foundation reactions only, no foundation design; PE seal is image stamp, not digitally signed. Reviewer: CHA Consulting (Christopher Manes) - no response. Req'd return per Fieldwire due 9/25. | D12: Product Data | E12: R.J. Haynie & Associates (Valmont Industries) | F12: 46265 | G12: 46283 | H12: 46290 | J12: Pending | K12: =IF(A12="","",IF(I12<>"",I12-G12,IF(G12<>"",TODAY()-G12,""))) -> 13 | M12: SUB-010_R0_Original_Procore_Export_2026-10-01.pdf; Submittal-010_Transmittal_Packaged.pdf (package INCLUDED, 99 pp) - folder: documents\submittals\SUB-010 - Mast Arm Pole Calcs | N12: Yes | O12: =IF(A12="","",MAX(F12+0,G12+0,H12+0,I12+0)) -> 46290 | P12: =IF(A12="","",IF(OR(J12="Approved",J12="Approved as Noted"),"",TODAY()-O12)) -> 6
K13: =IF(A13="","",IF(I13<>"",I13-G13,IF(G13<>"",TODAY()-G13,""))) | O13: =IF(A13="","",MAX(F13+0,G13+0,H13+0,I13+0)) | P13: =IF(A13="","",IF(OR(J13="Approved",J13="Approved as Noted"),"",TODAY()-O13))
K14: =IF(A14="","",IF(I14<>"",I14-G14,IF(G14<>"",TODAY()-G14,""))) | O14: =IF(A14="","",MAX(F14+0,G14+0,H14+0,I14+0)) | P14: =IF(A14="","",IF(OR(J14="Approved",J14="Approved as Noted"),"",TODAY()-O14))
K15: =IF(A15="","",IF(I15<>"",I15-G15,IF(G15<>"",TODAY()-G15,""))) | O15: =IF(A15="","",MAX(F15+0,G15+0,H15+0,I15+0)) | P15: =IF(A15="","",IF(OR(J15="Approved",J15="Approved as Noted"),"",TODAY()-O15))
K16: =IF(A16="","",IF(I16<>"",I16-G16,IF(G16<>"",TODAY()-G16,""))) | O16: =IF(A16="","",MAX(F16+0,G16+0,H16+0,I16+0)) | P16: =IF(A16="","",IF(OR(J16="Approved",J16="Approved as Noted"),"",TODAY()-O16))
K17: =IF(A17="","",IF(I17<>"",I17-G17,IF(G17<>"",TODAY()-G17,""))) | O17: =IF(A17="","",MAX(F17+0,G17+0,H17+0,I17+0)) | P17: =IF(A17="","",IF(OR(J17="Approved",J17="Approved as Noted"),"",TODAY()-O17))
K18: =IF(A18="","",IF(I18<>"",I18-G18,IF(G18<>"",TODAY()-G18,""))) | O18: =IF(A18="","",MAX(F18+0,G18+0,H18+0,I18+0)) | P18: =IF(A18="","",IF(OR(J18="Approved",J18="Approved as Noted"),"",TODAY()-O18))
K19: =IF(A19="","",IF(I19<>"",I19-G19,IF(G19<>"",TODAY()-G19,""))) | O19: =IF(A19="","",MAX(F19+0,G19+0,H19+0,I19+0)) | P19: =IF(A19="","",IF(OR(J19="Approved",J19="Approved as Noted"),"",TODAY()-O19))
K20: =IF(A20="","",IF(I20<>"",I20-G20,IF(G20<>"",TODAY()-G20,""))) | O20: =IF(A20="","",MAX(F20+0,G20+0,H20+0,I20+0)) | P20: =IF(A20="","",IF(OR(J20="Approved",J20="Approved as Noted"),"",TODAY()-O20))
K21: =IF(A21="","",IF(I21<>"",I21-G21,IF(G21<>"",TODAY()-G21,""))) | O21: =IF(A21="","",MAX(F21+0,G21+0,H21+0,I21+0)) | P21: =IF(A21="","",IF(OR(J21="Approved",J21="Approved as Noted"),"",TODAY()-O21))
K22: =IF(A22="","",IF(I22<>"",I22-G22,IF(G22<>"",TODAY()-G22,""))) | O22: =IF(A22="","",MAX(F22+0,G22+0,H22+0,I22+0)) | P22: =IF(A22="","",IF(OR(J22="Approved",J22="Approved as Noted"),"",TODAY()-O22))
K23: =IF(A23="","",IF(I23<>"",I23-G23,IF(G23<>"",TODAY()-G23,""))) | O23: =IF(A23="","",MAX(F23+0,G23+0,H23+0,I23+0)) | P23: =IF(A23="","",IF(OR(J23="Approved",J23="Approved as Noted"),"",TODAY()-O23))
K24: =IF(A24="","",IF(I24<>"",I24-G24,IF(G24<>"",TODAY()-G24,""))) | O24: =IF(A24="","",MAX(F24+0,G24+0,H24+0,I24+0)) | P24: =IF(A24="","",IF(OR(J24="Approved",J24="Approved as Noted"),"",TODAY()-O24))
... K298: =IF(A298="","",IF(I298<>"",I298-G298,IF(G298<>"",TODAY()-G298,""))) | O298: =IF(A298="","",MAX(F298+0,G298+0,H298+0,I298+0)) | P298: =IF(A298="","",IF(OR(J298="Approved",J298="Approved as Noted"),"",TODAY()-O298))
A301: Legend: gray-filled columns are for manual entry. Days in Review auto-calculates. Last Activity Date / Days Since Activity feed the Dashboard's Stale Items section. Row 2 is an example — delete before use.

Sheet Change Order Log
A1: PCO/CO # | B1: Date Initiated | C1: Description | D1: Source | E1: Trade(s) | F1: Linked RFI # | G1: Linked Claim # | H1: Cost Amount ($) | I1: Schedule Impact (days) | J1: Status | K1: Date Submitted to Owner | L1: Date Approved (Owner CO) | M1: Running Approved Total ($) | N1: Backup Documents | O1: Backup Required? | P1: Last Activity Date | Q1: Days Since Activity | R1: Bundled Into OCO #
A2: PCO-001 | B2: 46254 | C2: Base bid material/fuel price escalation true-up (Q1 2026 bid to July 2026 award); 5% OH&P | D2: Owner Request | E2: Earthwork/Site Utilities, Roofing, Low Voltage, Metal Panels, Plumbing, Rooftop Screens, Doors/Frames/Hardware | H2: 99986.52 | I2: 0 | J2: Pending | M2: =IF(A2="","",SUMIFS(H$2:H2,J$2:J2,"Approved")) -> 0 | N2: CO #01 - OCO Package - Pricing Escalation Rebalance.pdf (incl. PSI PCO-001 cost breakdown); 22_GC_CO_Template - CO01 rev1.xlsx; OCO #01 - Email Backup (7/29-8/3/2026) | O2: Yes | P2: =IF(A2="","",MAX(B2+0,K2+0,L2+0)) -> 46254 | Q2: =IF(A2="","",IF(OR(J2="Approved",J2="Rejected",J2="Void"),"",TODAY()-P2)) -> 42 | R2: OCO-01
A3: PCO-002 | B3: 46259 | C3: Allowance #01 - building demolition + ACM abatement; $224,903.34 drawn from $225,000 Demolition Allowance ($96.66 remaining); net $0 to Contract Sum; 9.8% GC OH&P | D3: Owner Request | E3: Demolition (Building & Site), Asbestos Abatement | H3: 0 | I3: 0 | J3: Pending | M3: =IF(A3="","",SUMIFS(H$2:H3,J$2:J3,"Approved")) -> 0 | N3: CO #02 - OCO Package - Building Demolition & Abatement.pdf; Lidl 1517 Demolition Scope.pdf (Cole's demo proposal $148,400); SCO - Coles Construction CO-02.xlsx; Lidl #1517 - Change Order #2 - Asbestos Abatement.pdf (Cole's CO-02 / SCO-LOG-001); 22_GC_CO_Template - CO02.xlsx | O3: Yes | P3: =IF(A3="","",MAX(B3+0,K3+0,L3+0)) -> 46259 | Q3: =IF(A3="","",IF(OR(J3="Approved",J3="Rejected",J3="Void"),"",TODAY()-P3)) -> 37 | R3: OCO-02
M4: =IF(A4="","",SUMIFS(H$2:H4,J$2:J4,"Approved")) | P4: =IF(A4="","",MAX(B4+0,K4+0,L4+0)) | Q4: =IF(A4="","",IF(OR(J4="Approved",J4="Rejected",J4="Void"),"",TODAY()-P4))
M5: =IF(A5="","",SUMIFS(H$2:H5,J$2:J5,"Approved")) | P5: =IF(A5="","",MAX(B5+0,K5+0,L5+0)) | Q5: =IF(A5="","",IF(OR(J5="Approved",J5="Rejected",J5="Void"),"",TODAY()-P5))
M6: =IF(A6="","",SUMIFS(H$2:H6,J$2:J6,"Approved")) | P6: =IF(A6="","",MAX(B6+0,K6+0,L6+0)) | Q6: =IF(A6="","",IF(OR(J6="Approved",J6="Rejected",J6="Void"),"",TODAY()-P6))
M7: =IF(A7="","",SUMIFS(H$2:H7,J$2:J7,"Approved")) | P7: =IF(A7="","",MAX(B7+0,K7+0,L7+0)) | Q7: =IF(A7="","",IF(OR(J7="Approved",J7="Rejected",J7="Void"),"",TODAY()-P7))
M8: =IF(A8="","",SUMIFS(H$2:H8,J$2:J8,"Approved")) | P8: =IF(A8="","",MAX(B8+0,K8+0,L8+0)) | Q8: =IF(A8="","",IF(OR(J8="Approved",J8="Rejected",J8="Void"),"",TODAY()-P8))
M9: =IF(A9="","",SUMIFS(H$2:H9,J$2:J9,"Approved")) | P9: =IF(A9="","",MAX(B9+0,K9+0,L9+0)) | Q9: =IF(A9="","",IF(OR(J9="Approved",J9="Rejected",J9="Void"),"",TODAY()-P9))
M10: =IF(A10="","",SUMIFS(H$2:H10,J$2:J10,"Approved")) | P10: =IF(A10="","",MAX(B10+0,K10+0,L10+0)) | Q10: =IF(A10="","",IF(OR(J10="Approved",J10="Rejected",J10="Void"),"",TODAY()-P10))
M11: =IF(A11="","",SUMIFS(H$2:H11,J$2:J11,"Approved")) | P11: =IF(A11="","",MAX(B11+0,K11+0,L11+0)) | Q11: =IF(A11="","",IF(OR(J11="Approved",J11="Rejected",J11="Void"),"",TODAY()-P11))
M12: =IF(A12="","",SUMIFS(H$2:H12,J$2:J12,"Approved")) | P12: =IF(A12="","",MAX(B12+0,K12+0,L12+0)) | Q12: =IF(A12="","",IF(OR(J12="Approved",J12="Rejected",J12="Void"),"",TODAY()-P12))
M13: =IF(A13="","",SUMIFS(H$2:H13,J$2:J13,"Approved")) | P13: =IF(A13="","",MAX(B13+0,K13+0,L13+0)) | Q13: =IF(A13="","",IF(OR(J13="Approved",J13="Rejected",J13="Void"),"",TODAY()-P13))
M14: =IF(A14="","",SUMIFS(H$2:H14,J$2:J14,"Approved")) | P14: =IF(A14="","",MAX(B14+0,K14+0,L14+0)) | Q14: =IF(A14="","",IF(OR(J14="Approved",J14="Rejected",J14="Void"),"",TODAY()-P14))
M15: =IF(A15="","",SUMIFS(H$2:H15,J$2:J15,"Approved")) | P15: =IF(A15="","",MAX(B15+0,K15+0,L15+0)) | Q15: =IF(A15="","",IF(OR(J15="Approved",J15="Rejected",J15="Void"),"",TODAY()-P15))
... M298: =IF(A298="","",SUMIFS(H$2:H298,J$2:J298,"Approved")) | P298: =IF(A298="","",MAX(B298+0,K298+0,L298+0)) | Q298: =IF(A298="","",IF(OR(J298="Approved",J298="Rejected",J298="Void"),"",TODAY()-P298))
A301: Running Approved Total sums col H where Status=Approved, in row order. Trade(s) tags which trade(s) the backup documents/cost breakdown apply to (comma-separated) — lets the weekly report and backup review group costs by trade. Last Activity Date / Days Since Activity feed the Dashboard's Stale Items section (blank once Approved/Rejected/Void). Bundled Into OCO # — a single Owner Change Order can combine multiple PCO rows (this is normal practice, e.g. bundling several CCDs into one OCO); tag every PCO row included in a given OCO with that OCO's number once it's issued for signature — use the Change Order Skill to build the actual signature-ready document. Row 2 is an example — delete before use.

Sheet Subcontractor CO Log
A1: SCO Log # | B1: Date Submitted | C1: Subcontractor Name | D1: Subcontract # | E1: Description | F1: Amount Requested ($) | G1: Schedule Impact Requested (days) | H1: Related Owner PCO/CO # | I1: Related RFI # | J1: Validity Assessment | K1: Status | L1: Date Reviewed | M1: Reviewed By | N1: Approved Amount ($) | O1: Running Approved Total — This Sub ($) | P1: Backup Documents | Q1: Backup Required? | R1: Last Activity Date | S1: Days Since Activity
A2: SCO-LOG-001 | B2: 46257 | C2: Cole's Construction | D2: 7 | E2: CO-02 Asbestos abatement (Georgia Environmental): Main Event Hall ACM floor mastic/carpet glue/carpet + ACM roofing mastic at 8 roof vents | F2: 56430 | G2: 0 | H2: PCO-002 / OCO-02 | J2: Valid change: Subcontract No. 7 (8/4/2026) Exhibit A covers selective/building demolition but no asbestos/ACM abatement, and PSI's bid (exclusion h) excludes asbestos abatement. ACM black floor mastic and roof penetration cement are confirmed in Owner's NOVA pre-demolition ACM survey (3/18/2021). Sub O&P 10% = prime contract 4.2 sub cap. Optional $5,500 debris line excluded (debris to be cleared before mobilization). Additional unsampled roof/mirror glue ACM to come as a separate SCO. Approved contingent on Lidl executing CO #02. | K2: Approved | L2: 46296 | M2: Luis Marcelino, General Manager | N2: 56430 | O2: =IF(C2="","",SUMIFS($N$2:N2,$C$2:C2,C2,$K$2:K2,"Approved")) -> 56430 | P2: Lidl #1517 - Change Order #2 - Asbestos Abatement.pdf; SCO - Coles Construction CO-02.xlsx | Q2: Yes | R2: =IF(C2="","",MAX(B2+0,L2+0)) -> 46296 | S2: =IF(C2="","",IF(OR(K2="Approved",K2="Rejected",K2="Void"),"",TODAY()-R2))
O3: =IF(C3="","",SUMIFS($N$2:N3,$C$2:C3,C3,$K$2:K3,"Approved")) | R3: =IF(C3="","",MAX(B3+0,L3+0)) | S3: =IF(C3="","",IF(OR(K3="Approved",K3="Rejected",K3="Void"),"",TODAY()-R3))
O4: =IF(C4="","",SUMIFS($N$2:N4,$C$2:C4,C4,$K$2:K4,"Approved")) | R4: =IF(C4="","",MAX(B4+0,L4+0)) | S4: =IF(C4="","",IF(OR(K4="Approved",K4="Rejected",K4="Void"),"",TODAY()-R4))
O5: =IF(C5="","",SUMIFS($N$2:N5,$C$2:C5,C5,$K$2:K5,"Approved")) | R5: =IF(C5="","",MAX(B5+0,L5+0)) | S5: =IF(C5="","",IF(OR(K5="Approved",K5="Rejected",K5="Void"),"",TODAY()-R5))
O6: =IF(C6="","",SUMIFS($N$2:N6,$C$2:C6,C6,$K$2:K6,"Approved")) | R6: =IF(C6="","",MAX(B6+0,L6+0)) | S6: =IF(C6="","",IF(OR(K6="Approved",K6="Rejected",K6="Void"),"",TODAY()-R6))
O7: =IF(C7="","",SUMIFS($N$2:N7,$C$2:C7,C7,$K$2:K7,"Approved")) | R7: =IF(C7="","",MAX(B7+0,L7+0)) | S7: =IF(C7="","",IF(OR(K7="Approved",K7="Rejected",K7="Void"),"",TODAY()-R7))
O8: =IF(C8="","",SUMIFS($N$2:N8,$C$2:C8,C8,$K$2:K8,"Approved")) | R8: =IF(C8="","",MAX(B8+0,L8+0)) | S8: =IF(C8="","",IF(OR(K8="Approved",K8="Rejected",K8="Void"),"",TODAY()-R8))
O9: =IF(C9="","",SUMIFS($N$2:N9,$C$2:C9,C9,$K$2:K9,"Approved")) | R9: =IF(C9="","",MAX(B9+0,L9+0)) | S9: =IF(C9="","",IF(OR(K9="Approved",K9="Rejected",K9="Void"),"",TODAY()-R9))
O10: =IF(C10="","",SUMIFS($N$2:N10,$C$2:C10,C10,$K$2:K10,"Approved")) | R10: =IF(C10="","",MAX(B10+0,L10+0)) | S10: =IF(C10="","",IF(OR(K10="Approved",K10="Rejected",K10="Void"),"",TODAY()-R10))
O11: =IF(C11="","",SUMIFS($N$2:N11,$C$2:C11,C11,$K$2:K11,"Approved")) | R11: =IF(C11="","",MAX(B11+0,L11+0)) | S11: =IF(C11="","",IF(OR(K11="Approved",K11="Rejected",K11="Void"),"",TODAY()-R11))
O12: =IF(C12="","",SUMIFS($N$2:N12,$C$2:C12,C12,$K$2:K12,"Approved")) | R12: =IF(C12="","",MAX(B12+0,L12+0)) | S12: =IF(C12="","",IF(OR(K12="Approved",K12="Rejected",K12="Void"),"",TODAY()-R12))
O13: =IF(C13="","",SUMIFS($N$2:N13,$C$2:C13,C13,$K$2:K13,"Approved")) | R13: =IF(C13="","",MAX(B13+0,L13+0)) | S13: =IF(C13="","",IF(OR(K13="Approved",K13="Rejected",K13="Void"),"",TODAY()-R13))
O14: =IF(C14="","",SUMIFS($N$2:N14,$C$2:C14,C14,$K$2:K14,"Approved")) | R14: =IF(C14="","",MAX(B14+0,L14+0)) | S14: =IF(C14="","",IF(OR(K14="Approved",K14="Rejected",K14="Void"),"",TODAY()-R14))
... O298: =IF(C298="","",SUMIFS($N$2:N298,$C$2:C298,C298,$K$2:K298,"Approved")) | R298: =IF(C298="","",MAX(B298+0,L298+0)) | S298: =IF(C298="","",IF(OR(K298="Approved",K298="Rejected",K298="Void"),"",TODAY()-R298))
A301: This log is GC review of costs a SUBCONTRACTOR submitted — separate from the Change Order Log above (which tracks the GC's own PCOs/COs to the Owner). Validity Assessment is where the review against the subcontract, drawings, and specs gets recorded before a status is set. Running Approved Total is per-subcontractor (tracks against their original Subcontract # value) — a formula, never type over column O. Row 2 is an example — delete before use.

Sheet Claims Log
A1: Claim # | B1: Date of Occurrence | C1: Notice Date | D1: Days to Notice | E1: Contract Notice Deadline (days) | F1: Notice Compliant? | G1: Description | H1: Cost Claimed ($) | I1: Time Claimed (days) | J1: Linked CO # | K1: Status | L1: Resolution | M1: Backup Documents | N1: Backup Required? | O1: Last Activity Date | P1: Days Since Activity
D2: =IF(A2="","",IF(AND(B2<>"",C2<>""),C2-B2,"")) | F2: =IF(A2="","",IF(AND(D2<>"",E2<>""),IF(D2<=E2,"Yes","NO - LATE"),"")) | O2: =IF(A2="","",MAX(B2+0,C2+0)) | P2: =IF(A2="","",IF(OR(K2="Approved",K2="Denied",K2="Withdrawn"),"",TODAY()-O2))
D3: =IF(A3="","",IF(AND(B3<>"",C3<>""),C3-B3,"")) | F3: =IF(A3="","",IF(AND(D3<>"",E3<>""),IF(D3<=E3,"Yes","NO - LATE"),"")) | O3: =IF(A3="","",MAX(B3+0,C3+0)) | P3: =IF(A3="","",IF(OR(K3="Approved",K3="Denied",K3="Withdrawn"),"",TODAY()-O3))
D4: =IF(A4="","",IF(AND(B4<>"",C4<>""),C4-B4,"")) | F4: =IF(A4="","",IF(AND(D4<>"",E4<>""),IF(D4<=E4,"Yes","NO - LATE"),"")) | O4: =IF(A4="","",MAX(B4+0,C4+0)) | P4: =IF(A4="","",IF(OR(K4="Approved",K4="Denied",K4="Withdrawn"),"",TODAY()-O4))
D5: =IF(A5="","",IF(AND(B5<>"",C5<>""),C5-B5,"")) | F5: =IF(A5="","",IF(AND(D5<>"",E5<>""),IF(D5<=E5,"Yes","NO - LATE"),"")) | O5: =IF(A5="","",MAX(B5+0,C5+0)) | P5: =IF(A5="","",IF(OR(K5="Approved",K5="Denied",K5="Withdrawn"),"",TODAY()-O5))
D6: =IF(A6="","",IF(AND(B6<>"",C6<>""),C6-B6,"")) | F6: =IF(A6="","",IF(AND(D6<>"",E6<>""),IF(D6<=E6,"Yes","NO - LATE"),"")) | O6: =IF(A6="","",MAX(B6+0,C6+0)) | P6: =IF(A6="","",IF(OR(K6="Approved",K6="Denied",K6="Withdrawn"),"",TODAY()-O6))
D7: =IF(A7="","",IF(AND(B7<>"",C7<>""),C7-B7,"")) | F7: =IF(A7="","",IF(AND(D7<>"",E7<>""),IF(D7<=E7,"Yes","NO - LATE"),"")) | O7: =IF(A7="","",MAX(B7+0,C7+0)) | P7: =IF(A7="","",IF(OR(K7="Approved",K7="Denied",K7="Withdrawn"),"",TODAY()-O7))
D8: =IF(A8="","",IF(AND(B8<>"",C8<>""),C8-B8,"")) | F8: =IF(A8="","",IF(AND(D8<>"",E8<>""),IF(D8<=E8,"Yes","NO - LATE"),"")) | O8: =IF(A8="","",MAX(B8+0,C8+0)) | P8: =IF(A8="","",IF(OR(K8="Approved",K8="Denied",K8="Withdrawn"),"",TODAY()-O8))
D9: =IF(A9="","",IF(AND(B9<>"",C9<>""),C9-B9,"")) | F9: =IF(A9="","",IF(AND(D9<>"",E9<>""),IF(D9<=E9,"Yes","NO - LATE"),"")) | O9: =IF(A9="","",MAX(B9+0,C9+0)) | P9: =IF(A9="","",IF(OR(K9="Approved",K9="Denied",K9="Withdrawn"),"",TODAY()-O9))
D10: =IF(A10="","",IF(AND(B10<>"",C10<>""),C10-B10,"")) | F10: =IF(A10="","",IF(AND(D10<>"",E10<>""),IF(D10<=E10,"Yes","NO - LATE"),"")) | O10: =IF(A10="","",MAX(B10+0,C10+0)) | P10: =IF(A10="","",IF(OR(K10="Approved",K10="Denied",K10="Withdrawn"),"",TODAY()-O10))
D11: =IF(A11="","",IF(AND(B11<>"",C11<>""),C11-B11,"")) | F11: =IF(A11="","",IF(AND(D11<>"",E11<>""),IF(D11<=E11,"Yes","NO - LATE"),"")) | O11: =IF(A11="","",MAX(B11+0,C11+0)) | P11: =IF(A11="","",IF(OR(K11="Approved",K11="Denied",K11="Withdrawn"),"",TODAY()-O11))
D12: =IF(A12="","",IF(AND(B12<>"",C12<>""),C12-B12,"")) | F12: =IF(A12="","",IF(AND(D12<>"",E12<>""),IF(D12<=E12,"Yes","NO - LATE"),"")) | O12: =IF(A12="","",MAX(B12+0,C12+0)) | P12: =IF(A12="","",IF(OR(K12="Approved",K12="Denied",K12="Withdrawn"),"",TODAY()-O12))
D13: =IF(A13="","",IF(AND(B13<>"",C13<>""),C13-B13,"")) | F13: =IF(A13="","",IF(AND(D13<>"",E13<>""),IF(D13<=E13,"Yes","NO - LATE"),"")) | O13: =IF(A13="","",MAX(B13+0,C13+0)) | P13: =IF(A13="","",IF(OR(K13="Approved",K13="Denied",K13="Withdrawn"),"",TODAY()-O13))
... D298: =IF(A298="","",IF(AND(B298<>"",C298<>""),C298-B298,"")) | F298: =IF(A298="","",IF(AND(D298<>"",E298<>""),IF(D298<=E298,"Yes","NO - LATE"),"")) | O298: =IF(A298="","",MAX(B298+0,C298+0)) | P298: =IF(A298="","",IF(OR(K298="Approved",K298="Denied",K298="Withdrawn"),"",TODAY()-O298))
A301: AIA A201-2017 §15.1.3: written notice of claim generally due within 21 days of the event. Confirm the actual deadline in your executed contract/exhibits before relying on this. Last Activity Date / Days Since Activity feed the Dashboard's Stale Items section. Row 2 is an example.

Sheet Risk Register
A1: Risk ID | B1: Date Identified | C1: Category | D1: Description | E1: Probability (1-5) | F1: Impact (1-5) | G1: Risk Score | H1: Priority | I1: Mitigation Plan | J1: Owner | K1: Linked CO # | L1: Linked Claim # | M1: Status | N1: Last Updated | O1: Days Since Update
G2: =IF(A2="","",IF(AND(E2<>"",F2<>""),E2*F2,"")) | H2: =IF(G2="","",IF(G2>=15,"High",IF(G2>=8,"Medium","Low"))) | O2: =IF(A2="","",IF(OR(M2="Closed",N2=""),"",TODAY()-N2))
G3: =IF(A3="","",IF(AND(E3<>"",F3<>""),E3*F3,"")) | H3: =IF(G3="","",IF(G3>=15,"High",IF(G3>=8,"Medium","Low"))) | O3: =IF(A3="","",IF(OR(M3="Closed",N3=""),"",TODAY()-N3))
G4: =IF(A4="","",IF(AND(E4<>"",F4<>""),E4*F4,"")) | H4: =IF(G4="","",IF(G4>=15,"High",IF(G4>=8,"Medium","Low"))) | O4: =IF(A4="","",IF(OR(M4="Closed",N4=""),"",TODAY()-N4))
G5: =IF(A5="","",IF(AND(E5<>"",F5<>""),E5*F5,"")) | H5: =IF(G5="","",IF(G5>=15,"High",IF(G5>=8,"Medium","Low"))) | O5: =IF(A5="","",IF(OR(M5="Closed",N5=""),"",TODAY()-N5))
G6: =IF(A6="","",IF(AND(E6<>"",F6<>""),E6*F6,"")) | H6: =IF(G6="","",IF(G6>=15,"High",IF(G6>=8,"Medium","Low"))) | O6: =IF(A6="","",IF(OR(M6="Closed",N6=""),"",TODAY()-N6))
G7: =IF(A7="","",IF(AND(E7<>"",F7<>""),E7*F7,"")) | H7: =IF(G7="","",IF(G7>=15,"High",IF(G7>=8,"Medium","Low"))) | O7: =IF(A7="","",IF(OR(M7="Closed",N7=""),"",TODAY()-N7))
G8: =IF(A8="","",IF(AND(E8<>"",F8<>""),E8*F8,"")) | H8: =IF(G8="","",IF(G8>=15,"High",IF(G8>=8,"Medium","Low"))) | O8: =IF(A8="","",IF(OR(M8="Closed",N8=""),"",TODAY()-N8))
G9: =IF(A9="","",IF(AND(E9<>"",F9<>""),E9*F9,"")) | H9: =IF(G9="","",IF(G9>=15,"High",IF(G9>=8,"Medium","Low"))) | O9: =IF(A9="","",IF(OR(M9="Closed",N9=""),"",TODAY()-N9))
G10: =IF(A10="","",IF(AND(E10<>"",F10<>""),E10*F10,"")) | H10: =IF(G10="","",IF(G10>=15,"High",IF(G10>=8,"Medium","Low"))) | O10: =IF(A10="","",IF(OR(M10="Closed",N10=""),"",TODAY()-N10))
G11: =IF(A11="","",IF(AND(E11<>"",F11<>""),E11*F11,"")) | H11: =IF(G11="","",IF(G11>=15,"High",IF(G11>=8,"Medium","Low"))) | O11: =IF(A11="","",IF(OR(M11="Closed",N11=""),"",TODAY()-N11))
G12: =IF(A12="","",IF(AND(E12<>"",F12<>""),E12*F12,"")) | H12: =IF(G12="","",IF(G12>=15,"High",IF(G12>=8,"Medium","Low"))) | O12: =IF(A12="","",IF(OR(M12="Closed",N12=""),"",TODAY()-N12))
G13: =IF(A13="","",IF(AND(E13<>"",F13<>""),E13*F13,"")) | H13: =IF(G13="","",IF(G13>=15,"High",IF(G13>=8,"Medium","Low"))) | O13: =IF(A13="","",IF(OR(M13="Closed",N13=""),"",TODAY()-N13))
... G298: =IF(A298="","",IF(AND(E298<>"",F298<>""),E298*F298,"")) | H298: =IF(G298="","",IF(G298>=15,"High",IF(G298>=8,"Medium","Low"))) | O298: =IF(A298="","",IF(OR(M298="Closed",N298=""),"",TODAY()-N298))
A301: Risk Score = Probability x Impact (1-5 scale each). Last Updated is MANUAL — update it yourself whenever you touch a risk (there's no second date field to compute this from automatically); Days Since Update feeds the Dashboard's Stale Items section. Row 2 is an example — delete before use.

Sheet Daily Log
A1: Date | B1: Weather | C1: Temp (F) | D1: Crew Count | E1: Subs on Site | F1: Work Performed | G1: Equipment on Site | H1: Deliveries | I1: Visitors | J1: Safety Incidents | K1: Delays / Issues | L1: Linked RFI #(s) | M1: Linked Submittal #(s) | N1: Photo Ref #(s)
A301: One row per working day. Row 2 is an example — delete before use.

Sheet Meeting Minutes Log
A1: Meeting # | B1: Date | C1: Type | D1: Attendees | E1: Key Discussion Point | F1: Action Item | G1: Responsible Party | H1: Due Date | I1: Status | J1: Linked RFI/CO/Risk # | K1: Backup Documents
A2: OAC-001 | B2: 46296 | C2: OAC | D2: Luis F. Marcelino (Place Services Inc.); Tucker Teague (Place Services Inc.); Jens Byer; Chris Manes (CHA Consulting, Inc.); Gabriela Camarillo (Progressive Companies) | E2: Mobilization and demolition start - on site Mon 10/5/2026 | F2: Confirm Monday 10/5 mobilization to Jens and Chris | G2: Luis F. Marcelino | H2: Before 10/5/2026 | I2: Open | K2: documents\meeting minutes\OAC\Meeting_Minutes_OAC-001_2026-10-01_Rev1.pdf
A3: OAC-001 | B3: 46296 | C3: OAC | D3: Luis F. Marcelino (Place Services Inc.); Tucker Teague (Place Services Inc.); Jens Byer; Chris Manes (CHA Consulting, Inc.); Gabriela Camarillo (Progressive Companies) | E3: County pre-con meetings - traffic/ROW (R.J. Haynes) | F3: Schedule county pre-con for traffic / right-of-way work | G3: R.J. Haynes | H3: Before any ROW work - DATE NEEDED | I3: Open | J3: RFI-006
A4: OAC-001 | B4: 46296 | C4: OAC | D4: Luis F. Marcelino (Place Services Inc.); Tucker Teague (Place Services Inc.); Jens Byer; Chris Manes (CHA Consulting, Inc.); Gabriela Camarillo (Progressive Companies) | E4: County pre-con meetings - utility work (Cole's Construction, site contractor) | F4: Schedule county pre-con for utility work | G4: Cole's Construction | H4: Before utility work - DATE NEEDED | I4: Open
A5: OAC-001 | B5: 46296 | C5: OAC | D5: Luis F. Marcelino (Place Services Inc.); Tucker Teague (Place Services Inc.); Jens Byer; Chris Manes (CHA Consulting, Inc.); Gabriela Camarillo (Progressive Companies) | E5: County pre-con meetings - correspondence distribution | F5: Forward county correspondence to Jens and Chris | G5: Luis F. Marcelino | H5: Ongoing | I5: Open
A6: OAC-001 | B6: 46296 | C6: OAC | D6: Luis F. Marcelino (Place Services Inc.); Tucker Teague (Place Services Inc.); Jens Byer; Chris Manes (CHA Consulting, Inc.); Gabriela Camarillo (Progressive Companies) | E6: County inspector asked to meet team before work starts | F6: Send inspector contact information to Luis | G6: Chris Manes | H6: TBD - DATE NEEDED | I6: Open
A7: OAC-001 | B7: 46296 | C7: OAC | D7: Luis F. Marcelino (Place Services Inc.); Tucker Teague (Place Services Inc.); Jens Byer; Chris Manes (CHA Consulting, Inc.); Gabriela Camarillo (Progressive Companies) | E7: County inspector asked to meet team before work starts | F7: Contact inspector before starting work (including demo, if requested) | G7: Luis F. Marcelino | H7: Before 10/5/2026 | I7: Open
A8: OAC-001 | B8: 46296 | C8: OAC | D8: Luis F. Marcelino (Place Services Inc.); Tucker Teague (Place Services Inc.); Jens Byer; Chris Manes (CHA Consulting, Inc.); Gabriela Camarillo (Progressive Companies) | E8: Civil plan revisions resubmission on hold until Phase 1 E&S installed | F8: Resubmit civil plan revisions; keep team informed of timing | G8: Chris Manes | H8: After Phase 1 E&S installed - DATE NEEDED | I8: Open
A9: OAC-001 | B9: 46296 | C9: OAC | D9: Luis F. Marcelino (Place Services Inc.); Tucker Teague (Place Services Inc.); Jens Byer; Chris Manes (CHA Consulting, Inc.); Gabriela Camarillo (Progressive Companies) | E9: Communication - copy Tucker Teague and Bobby McTeague on all emails | F9: Add Tucker Teague and Bobby McTeague to all project correspondence | G9: Jens Byer; Chris Manes | H9: Immediately | I9: Open
A10: OAC-001 | B10: 46296 | C10: OAC | D10: Luis F. Marcelino (Place Services Inc.); Tucker Teague (Place Services Inc.); Jens Byer; Chris Manes (CHA Consulting, Inc.); Gabriela Camarillo (Progressive Companies) | E10: Recurring OAC meeting - Thursday afternoons | F10: Send recurring Thursday-afternoon OAC invite to all attendees | G10: Jens Byer | H10: 46303 | I10: Open
A11: OAC-001 | B11: 46296 | C11: OAC | D11: Luis F. Marcelino (Place Services Inc.); Tucker Teague (Place Services Inc.); Jens Byer; Chris Manes (CHA Consulting, Inc.); Gabriela Camarillo (Progressive Companies) | E11: Site visit by Jens Byer within 2-3 weeks | F11: Schedule site visit | G11: Jens Byer | H11: 10/22/2026 (approx.) | I11: Open
A12: OAC-001 | B12: 46296 | C12: OAC | D12: Luis F. Marcelino (Place Services Inc.); Tucker Teague (Place Services Inc.); Jens Byer; Chris Manes (CHA Consulting, Inc.); Gabriela Camarillo (Progressive Companies) | E12: Contract and Procore - executed contract upload | F12: Upload fully executed contract to Procore | G12: Jens Byer | H12: TBD - DATE NEEDED | I12: Open
A13: OAC-001 | B13: 46296 | C13: OAC | D13: Luis F. Marcelino (Place Services Inc.); Tucker Teague (Place Services Inc.); Jens Byer; Chris Manes (CHA Consulting, Inc.); Gabriela Camarillo (Progressive Companies) | E13: Contract and Procore - inflation change item; demo/abatement against allowance | F13: Log inflation discussion in Procore as a change item | G13: Luis F. Marcelino | H13: After contract upload - DATE NEEDED | I13: Open | J13: PCO pending (not yet in Change Order Log)
A301: One row per discussion point / action item (a single meeting spans several rows). Row 2 is an example.

Sheet Contract Review Log
A1: Item # | B1: Contract / Subcontract | C1: Clause Ref | D1: Standard Position (Playbook) | E1: Actual Clause (Summary) | F1: Deviation? | G1: Risk Level | H1: Recommended Redline | I1: Status | J1: Backup Documents
A301: One row per clause reviewed against your standard playbook position. Row 2 is an example — delete before use.

Sheet Schedule
A1: Activity / Milestone | B1: Baseline Start | C1: Baseline Finish | D1: Forecast Start | E1: Forecast Finish | F1: % Complete | G1: Variance (days) | H1: Status | I1: Critical Path? | J1: Responsible | K1: Notes
G2: =IF(A2="","",IF(AND(C2<>"",E2<>""),E2-C2,"")) | H2: =IF(A2="","",IF(G2="","",IF(G2>5,"Delayed",IF(G2>0,"At Risk","On Track"))))
G3: =IF(A3="","",IF(AND(C3<>"",E3<>""),E3-C3,"")) | H3: =IF(A3="","",IF(G3="","",IF(G3>5,"Delayed",IF(G3>0,"At Risk","On Track"))))
G4: =IF(A4="","",IF(AND(C4<>"",E4<>""),E4-C4,"")) | H4: =IF(A4="","",IF(G4="","",IF(G4>5,"Delayed",IF(G4>0,"At Risk","On Track"))))
G5: =IF(A5="","",IF(AND(C5<>"",E5<>""),E5-C5,"")) | H5: =IF(A5="","",IF(G5="","",IF(G5>5,"Delayed",IF(G5>0,"At Risk","On Track"))))
G6: =IF(A6="","",IF(AND(C6<>"",E6<>""),E6-C6,"")) | H6: =IF(A6="","",IF(G6="","",IF(G6>5,"Delayed",IF(G6>0,"At Risk","On Track"))))
G7: =IF(A7="","",IF(AND(C7<>"",E7<>""),E7-C7,"")) | H7: =IF(A7="","",IF(G7="","",IF(G7>5,"Delayed",IF(G7>0,"At Risk","On Track"))))
G8: =IF(A8="","",IF(AND(C8<>"",E8<>""),E8-C8,"")) | H8: =IF(A8="","",IF(G8="","",IF(G8>5,"Delayed",IF(G8>0,"At Risk","On Track"))))
G9: =IF(A9="","",IF(AND(C9<>"",E9<>""),E9-C9,"")) | H9: =IF(A9="","",IF(G9="","",IF(G9>5,"Delayed",IF(G9>0,"At Risk","On Track"))))
G10: =IF(A10="","",IF(AND(C10<>"",E10<>""),E10-C10,"")) | H10: =IF(A10="","",IF(G10="","",IF(G10>5,"Delayed",IF(G10>0,"At Risk","On Track"))))
G11: =IF(A11="","",IF(AND(C11<>"",E11<>""),E11-C11,"")) | H11: =IF(A11="","",IF(G11="","",IF(G11>5,"Delayed",IF(G11>0,"At Risk","On Track"))))
G12: =IF(A12="","",IF(AND(C12<>"",E12<>""),E12-C12,"")) | H12: =IF(A12="","",IF(G12="","",IF(G12>5,"Delayed",IF(G12>0,"At Risk","On Track"))))
G13: =IF(A13="","",IF(AND(C13<>"",E13<>""),E13-C13,"")) | H13: =IF(A13="","",IF(G13="","",IF(G13>5,"Delayed",IF(G13>0,"At Risk","On Track"))))
... G298: =IF(A298="","",IF(AND(C298<>"",E298<>""),E298-C298,"")) | H298: =IF(A298="","",IF(G298="","",IF(G298>5,"Delayed",IF(G298>0,"At Risk","On Track"))))
A301: Variance = Forecast Finish - Baseline Finish. Status: >5 days late = Delayed, 1-5 = At Risk, 0 or ahead = On Track. Row 2 is an example — delete before use.

Sheet Contract Milestones
A1: Milestone | B1: Contract / Target Date | C1: Actual / Forecast Date | D1: Status | E1: Responsible | F1: Notes
D2: =IF(A2="","",IF(C2<>"",IF(C2<=B2,"Met - On Time","Met - Late"),IF(TODAY()>B2,"Missed",IF(B2-TODAY()<=14,"Due Soon","On Track"))))
D3: =IF(A3="","",IF(C3<>"",IF(C3<=B3,"Met - On Time","Met - Late"),IF(TODAY()>B3,"Missed",IF(B3-TODAY()<=14,"Due Soon","On Track"))))
D4: =IF(A4="","",IF(C4<>"",IF(C4<=B4,"Met - On Time","Met - Late"),IF(TODAY()>B4,"Missed",IF(B4-TODAY()<=14,"Due Soon","On Track"))))
D5: =IF(A5="","",IF(C5<>"",IF(C5<=B5,"Met - On Time","Met - Late"),IF(TODAY()>B5,"Missed",IF(B5-TODAY()<=14,"Due Soon","On Track"))))
D6: =IF(A6="","",IF(C6<>"",IF(C6<=B6,"Met - On Time","Met - Late"),IF(TODAY()>B6,"Missed",IF(B6-TODAY()<=14,"Due Soon","On Track"))))
D7: =IF(A7="","",IF(C7<>"",IF(C7<=B7,"Met - On Time","Met - Late"),IF(TODAY()>B7,"Missed",IF(B7-TODAY()<=14,"Due Soon","On Track"))))
D8: =IF(A8="","",IF(C8<>"",IF(C8<=B8,"Met - On Time","Met - Late"),IF(TODAY()>B8,"Missed",IF(B8-TODAY()<=14,"Due Soon","On Track"))))
D9: =IF(A9="","",IF(C9<>"",IF(C9<=B9,"Met - On Time","Met - Late"),IF(TODAY()>B9,"Missed",IF(B9-TODAY()<=14,"Due Soon","On Track"))))
D10: =IF(A10="","",IF(C10<>"",IF(C10<=B10,"Met - On Time","Met - Late"),IF(TODAY()>B10,"Missed",IF(B10-TODAY()<=14,"Due Soon","On Track"))))
D11: =IF(A11="","",IF(C11<>"",IF(C11<=B11,"Met - On Time","Met - Late"),IF(TODAY()>B11,"Missed",IF(B11-TODAY()<=14,"Due Soon","On Track"))))
D12: =IF(A12="","",IF(C12<>"",IF(C12<=B12,"Met - On Time","Met - Late"),IF(TODAY()>B12,"Missed",IF(B12-TODAY()<=14,"Due Soon","On Track"))))
D13: =IF(A13="","",IF(C13<>"",IF(C13<=B13,"Met - On Time","Met - Late"),IF(TODAY()>B13,"Missed",IF(B13-TODAY()<=14,"Due Soon","On Track"))))
... D295: =IF(A295="","",IF(C295<>"",IF(C295<=B295,"Met - On Time","Met - Late"),IF(TODAY()>B295,"Missed",IF(B295-TODAY()<=14,"Due Soon","On Track"))))
A298: Status: filled Actual/Forecast Date compares to Target (On Time / Late); no date yet compares Target to today (On Track / Due Soon within 14 days / Missed). These are the owner-contract dates (Substantial Completion, etc.) — distinct from the internal Schedule tab's activity-level forecasting. Rows 2-5 are examples — delete before use, and leave a milestone's row blank entirely if your contract doesn't set that date.

Sheet 3-Week Look-Ahead
A1: Week | B1: Week Starting | C1: Activity | D1: Location / Area | E1: Responsible (Sub) | F1: Predecessor / Constraint | G1: Status | H1: Notes
A298: This tab is a WEEKLY FEED you provide — paste/replace it each week rather than having Claude generate or recalculate it. Rolling 3-week window: drop week 1 as it completes and add a new week 3. Rows 2-5 are examples — delete before use.

Sheet Photo Log
A1: Photo Ref # | B1: Date Taken | C1: Area / Location | D1: Description | E1: Linked Daily Log Date | F1: Linked RFI/CO/Risk # | G1: File Name | H1: Include in Next Owner Report?
A301: Index of jobsite photos. Keep the actual image files in the same folder/Drive as this workbook, named to match File Name. Row 2 is an example — delete before use.

Sheet Permit Tracker
B2: Project: | C2: =IF('Project Info'!C5="","",'Project Info'!C5) -> Norcross, GA | P2: Total Trades | Q2: =SUMPRODUCT((A6:A303<>"")*1) -> 0 | R2: Issued / In Hand | S2: =COUNTIF(E6:E303,"In Hand") -> 0
B3: AHJ / Jurisdiction: | C3: =IF('Project Info'!C9="","",'Project Info'!C9) -> Gwinnett County, GA; Norcross, GA | P3: Action Needed | Q3: =COUNTIF(J6:J303,"ACTION NEEDED") -> 0 | R3: Expiring Soon | S3: =COUNTIF(J6:J303,"EXPIRING SOON") -> 0
A5: Trade / Permit Type | B5: Permit Required? | C5: Responsible Party | D5: Permit Number | E5: Status | F5: Application Date | G5: Approval / Issue Date | H5: Expiration Date | I5: Notes / Next Action | J5: Flag | K5: Backup Documents | L5: Backup Required? | M5: Last Activity Date | N5: Days Since Activity
J6: =IF(A6="","",IF(OR(E6="Rejected",E6="Expired"),"ACTION NEEDED",IF(AND(B6="Yes",E6="Not Started"),"ACTION NEEDED",IF(AND(E6="In Hand",H6<>"",H6-TODAY()<=30,H6-TODAY()>=0),"EXPIRING SOON","")))) | M6: =IF(A6="","",MAX(F6+0,G6+0)) | N6: =IF(A6="","",IF(OR(E6="In Hand",E6="Rejected"),"",TODAY()-M6))
J7: =IF(A7="","",IF(OR(E7="Rejected",E7="Expired"),"ACTION NEEDED",IF(AND(B7="Yes",E7="Not Started"),"ACTION NEEDED",IF(AND(E7="In Hand",H7<>"",H7-TODAY()<=30,H7-TODAY()>=0),"EXPIRING SOON","")))) | M7: =IF(A7="","",MAX(F7+0,G7+0)) | N7: =IF(A7="","",IF(OR(E7="In Hand",E7="Rejected"),"",TODAY()-M7))
J8: =IF(A8="","",IF(OR(E8="Rejected",E8="Expired"),"ACTION NEEDED",IF(AND(B8="Yes",E8="Not Started"),"ACTION NEEDED",IF(AND(E8="In Hand",H8<>"",H8-TODAY()<=30,H8-TODAY()>=0),"EXPIRING SOON","")))) | M8: =IF(A8="","",MAX(F8+0,G8+0)) | N8: =IF(A8="","",IF(OR(E8="In Hand",E8="Rejected"),"",TODAY()-M8))
